Workbook

Sheet Outputs
B2: Dashboard and Output
B3: all figures in millions of New Taiwan Dollors NTD unless stated
F6: Enterprise Value | N6: Price per Share
F7: Terminal Growth Rate | N7: Terminal Growth Rate
C8: =Model!D546 -> 66837912 | D8: =Model!E546 -> 0.0037290889 | E8: =Model!F546 -> 0.0049629316 | F8: =Model!G546 -> 0.0061922463 | G8: =Model!H546 -> 0.0074170718 | H8: =Model!I546 -> 0.008637446 | L8: =Model!M546 -> 0.0037290889 | M8: =Model!N546 -> 0.0049629316 | N8: =Model!O546 -> 0.0061922463 | O8: =Model!P546 -> 0.0074170718 | P8: =Model!Q546 -> 0.008637446 | R8: Quarterly adjustmenst have been done to all the inputs of the sensitivity table
B9: WACC | C9: =Model!D547 -> 0.018244601 | D9: =Model!E547 -> 69393180 | E9: =Model!F547 -> 75631955 | F9: =Model!G547 -> 83118185 | G9: =Model!H547 -> 92267688 | H9: =Model!I547 -> 1.037042e+08 | J9: WACC | K9: =Model!L547 -> 0.018244601 | L9: =Model!M547 -> 2752.2581 | M9: =Model!N547 -> 2992.8402 | N9: =Model!O547 -> 3281.5271 | O9: =Model!P547 -> 3634.3539 | P9: =Model!Q547 -> 4075.3731 | S9: WACC annual | U9: WACC quarter | W9: TGR annual | Y9: TGR quarter
C10: =Model!D548 -> 0.020015981 | D10: =Model!E548 -> 61969610 | E10: =Model!F548 -> 66865974 | F10: =Model!G548 -> 72613618 | G10: =Model!H548 -> 79455767 | H10: =Model!I548 -> 87738056 | K10: =Model!L548 -> 0.020015981 | L10: =Model!M548 -> 2465.9875 | M10: =Model!N548 -> 2654.803 | N10: =Model!O548 -> 2876.4459 | O10: =Model!P548 -> 3140.2956 | P10: =Model!Q548 -> 3459.6805 | S10: 0.0775 | U10: =((1+S10)^(1/4))-1 -> 0.018836088 | W10: 0.015 | Y10: =((1+W10)^(1/4))-1 -> 0.0037290889
C11: =Model!D549 -> 0.021231269 | D11: =Model!E549 -> 57745561 | E11: =Model!F549 -> 61955931 | F11: =Model!G549 -> 66837912 | G11: =Model!H549 -> 72566199 | H11: =Model!I549 -> 79381823 | K11: =Model!L549 -> 0.021231269 | L11: =Model!M549 -> 2303.098 | M11: =Model!N549 -> 2465.46 | N11: =Model!O549 -> 2653.7209 | O11: =Model!P549 -> 2874.6173 | P11: =Model!Q549 -> 3137.4441 | S11: 0.0825 | U11: =((1+S11)^(1/4))-1 -> 0.020015981 | W11: 0.02 | Y11: =((1+W11)^(1/4))-1 -> 0.0049629316
C12: =Model!D550 -> 0.022947935 | D12: =Model!E550 -> 52688995 | E12: =Model!F550 -> 56150766 | F12: =Model!G550 -> 60106862 | G12: =Model!H550 -> 64671358 | H12: =Model!I550 -> 69996355 | K12: =Model!L550 -> 0.022947935 | L12: =Model!M550 -> 2108.1047 | M12: =Model!N550 -> 2241.5989 | N12: =Model!O550 -> 2394.1555 | O12: =Model!P550 -> 2570.1733 | P12: =Model!Q550 -> 2775.518 | S12: =Inputs!N83 -> 0.087668161 | U12: =((1+S12)^(1/4))-1 -> 0.021231269 | W12: 0.025 | Y12: =((1+W12)^(1/4))-1 -> 0.0061922463
C13: =Model!D551 -> 0.024695077 | D13: =Model!E551 -> 48392772 | E13: =Model!F551 -> 51279555 | F13: =Model!G551 -> 54538632 | G13: =Model!H551 -> 58247030 | H13: =Model!I551 -> 62504602 | K13: =Model!L551 -> 0.024695077 | L13: =Model!M551 -> 1942.4321 | M13: =Model!N551 -> 2053.7534 | N13: =Model!O551 -> 2179.4312 | O13: =Model!P551 -> 2322.4359 | P13: =Model!Q551 -> 2486.618 | S13: 0.095 | U13: =((1+S13)^(1/4))-1 -> 0.022947935 | W13: 0.03 | Y13: =((1+W13)^(1/4))-1 -> 0.0074170718
S14: 0.1025 | U14: =((1+S14)^(1/4))-1 -> 0.024695077 | W14: 0.035 | Y14: =((1+W14)^(1/4))-1 -> 0.008637446
F16: Equity Value | N16: Upside/(Downside) to Current Price
F17: Terminal Growth Rate | N17: Terminal Growth Rate
D18: =Model!E556 -> 0.0037290889 | E18: =Model!F556 -> 0.0049629316 | F18: =Model!G556 -> 0.0061922463 | G18: =Model!H556 -> 0.0074170718 | H18: =Model!I556 -> 0.008637446 | L18: =Model!M556 -> 0.0037290889 | M18: =Model!N556 -> 0.0049629316 | N18: =Model!O556 -> 0.0061922463 | O18: =Model!P556 -> 0.0074170718 | P18: =Model!Q556 -> 0.008637446
B19: WACC | C19: =Model!D557 -> 0.018244601 | D19: =Model!E557 -> 71371557 | E19: =Model!F557 -> 77610333 | F19: =Model!G557 -> 85096562 | G19: =Model!H557 -> 94246066 | H19: =Model!I557 -> 1.0568257e+08 | J19: WACC | K19: =Model!L557 -> 0.018244601 | L19: =Model!M557 -> 0.17117366 | M19: =Model!N557 -> 0.27354903 | N19: =Model!O557 -> 0.39639453 | O19: =Model!P557 -> 0.54653358 | P19: =Model!Q557 -> 0.73420131
C20: =Model!D558 -> 0.020015981 | D20: =Model!E558 -> 63947987 | E20: =Model!F558 -> 68844351 | F20: =Model!G558 -> 74591996 | G20: =Model!H558 -> 81434145 | H20: =Model!I558 -> 89716434 | K20: =Model!L558 -> 0.020015981 | L20: =Model!M558 -> 0.049356367 | M20: =Model!N558 -> 0.1297034 | N20: =Model!O558 -> 0.22401954 | O20: =Model!P558 -> 0.33629599 | P20: =Model!Q558 -> 0.47220445
C21: =Model!D559 -> 0.021231269 | D21: =Model!E559 -> 59723938 | E21: =Model!F559 -> 63934308 | F21: =Model!G559 -> 68816289 | G21: =Model!H559 -> 74544576 | H21: =Model!I559 -> 81360200 | K21: =Model!L559 -> 0.021231269 | L21: =Model!M559 -> -0.019958286 | M21: =Model!N559 -> 0.049131904 | N21: =Model!O559 -> 0.12924292 | O21: =Model!P559 -> 0.22324141 | P21: =Model!Q559 -> 0.33508259
C22: =Model!D560 -> 0.022947935 | D22: =Model!E560 -> 54667372 | E22: =Model!F560 -> 58129144 | F22: =Model!G560 -> 62085239 | G22: =Model!H560 -> 66649735 | H22: =Model!I560 -> 71974733 | K22: =Model!L560 -> 0.022947935 | L22: =Model!M560 -> -0.10293415 | M22: =Model!N560 -> -0.046128109 | N22: =Model!O560 -> 0.018789555 | O22: =Model!P560 -> 0.093690781 | P22: =Model!Q560 -> 0.18107149
C23: =Model!D561 -> 0.024695077 | D23: =Model!E561 -> 50371150 | E23: =Model!F561 -> 53257932 | F23: =Model!G561 -> 56517009 | G23: =Model!H561 -> 60225408 | H23: =Model!I561 -> 64482979 | K23: =Model!L561 -> 0.024695077 | L23: =Model!M561 -> -0.17343314 | M23: =Model!N561 -> -0.1260624 | N23: =Model!O561 -> -0.07258248 | O23: =Model!P561 -> -0.011729405 | P23: =Model!Q561 -> 0.058135337
E27: Enterprise | F27: Equity | G27: Equity
E28: Value | F28: Value | G28: Per Share | R28: As on June 1st June 2026
C29: Best Case | D29: 1 | E29: =Model!H547 -> 92267688 | F29: =Model!H557 -> 94246066 | G29: =F29/Inputs!$G$89 -> 3634.3539 | J29: 12-Month Target Price | L29: (NTD/sh) | M29: =SUM('Key Ratios & Metrics'!G225:J225)*Model!G574 -> 2881.004
C30: Base Case | D30: 2 | E30: =Model!G549 -> 66837912 | F30: =Model!G559 -> 68816289 | G30: =F30/Inputs!$G$89 -> 2653.7209 | J30: Near Term Target Price | L30: (NTD/sh) | M30: =Model!T531 -> 2653.7789
C31: Bear Case | D31: 3 | E31: =Model!E551 -> 48392772 | F31: =Model!E561 -> 50371150 | G31: =F31/Inputs!$G$89 -> 1942.4321 | J31: Current Price | L31: (NTD/sh) | M31: =Inputs!G90 -> 2350

Sheet Inputs
B1: Drivers and Inputs | K1: Forecasts | R1: Notes:
B2: all figures in millions of New Taiwan Dollors NTD unless stated | I2: 46203 | J2: 46295 | K2: 46386 | L2: 46476 | M2: 46568 | N2: Term
B4: Cost of Sales | I4: 0.335 | J4: 0.3325 | K4: 0.33 | L4: 0.3275 | M4: 0.325 | N4: 0.323 | R4: Most of revenue is by wafer business and growth from increasing demand for the HPC and AI
R5: in historicals tab revenue is calculated by both technology and platforms taken directly from the investors presentation
B6: SG&A | I6: 0.023 | J6: 0.021 | K6: 0.02 | L6: 0.0195 | M6: 0.019 | N6: 0.019 | R6: which is based on the % revenue contribution by each technology and platform
R7: under technology sub 7nm were given main priority for the revenue growth since these tech makes up most of the demand
B8: R&D | I8: 0.0595 | J8: 0.059 | K8: 0.0585 | L8: 0.058 | M8: 0.058 | N8: 0.058 | R8: escpecially 3nm, and newly developing 2nm not considered in modelling since its neither available in the market yet nor
R9: its specifications
B10: Account Recievables Days | I10: 28.25 | J10: 28.75 | K10: 28.5 | L10: 28 | M10: 27.75 | N10: 27.25
B11: Inventory Days | I11: 72.25 | J11: 72.5 | K11: 73 | L11: 73 | M11: 72 | N11: 72
B12: Account Payable Days | I12: 22.75 | J12: 23 | K12: 23.5 | L12: 24 | M12: 23 | N12: 24
B15: Taxes | I15: Assets & Depreciation
B17: Tax Rate | F17: 0.16 | I17: First Year Accounting Depreciation/ Depreciable First year Amount | N17: 1
B18: First Year Tax Depreciation | F18: 0.4 | I18: Usefull life: Existing assets | N18: 10
B19: Blended tax Depreciation Rate | F19: 0.2 | I19: Usefull life: New assets | N19: 12
B20: Tax basis for Assets | F20: 4108129.3 | G20: end of Q1 2026
B21: Tax Losses | F21: 0 | G21: end of Q1 2026 | I21: Net PP&E at the End of 2026FY | N21: 3954679
I22: Gross PP&E at the End of 2026FY | N22: 8052961.7
I23: Depreciable Assets | N23: 6755752
B25: Interest Rates | I25: Other Single Inputs
B27: Cash Balances | F27: 0.01 | I27: Dividend Payout ratio | N27: 0.23
B28: Revolving Credit Line | F28: 0.01125 | I28: NCI Dividend/Distribution | N28: 0
B29: Bonds | F29: 0.006 | I29: Total Debt | N29: =Historicals!K142 -> 1057259.7
B30: Bank Loans | F30: 0.005 | I30: Cash | N30: =Historicals!K83 -> 3035637
I31: Market Capitalization
B32: Dates
B34: Valuation Date | F34: 46143
B35: First Expected Cash Flow | F35: 46157
B36: First Quarter End for Forecast | F36: 46203
B37: First Forecast | F37: 46174
B38: Incorrect Date Set for Valuation? | F38: =IF(F34>F35,1,0) -> 0
B39: Incorrect Date Set for First Cash Flow? | F39: =IF(F35>F36,1,0) -> 0
B40: Days in Period
B43: Weighted Average Cost of Capital
J45: Avg | K45: Debt / | L45: Debt / | M45: Unlevered | N45: Levered
B46: Name | E46: Exchange | F46: Ticker | G46: Currency | H46: Debt | I46: Equity | J46: Tax Rate 1 | K46: Equity | L46: Capital | M46: Beta 2 | N46: Beta 3
B48: Samsung Electronics | E48: KRX | F48: 005930 | G48: KRW | H48: 28138800 | I48: 1500000000 | J48: =H48/I48 -> 0.0187592 | K48: 0.185 | L48: =H48/(I48+H48) -> 0.018413772 | M48: 1.49 | N48: =M48/(1+(1-J48)*K48) -> 1.2610772
B49: Semiconductor Manufacturing International Corp | G49: CNY | H49: 102805 | I49: 548500 | J49: 0.1125 | K49: =H49/I49 -> 0.18742935 | L49: =H49/(H49+I49) -> 0.15784464 | M49: 1.15 | N49: =M49/(1+(1-J49)*K49) -> 0.98598736
B50: Intel Corporation | E50: NASDAQ | F50: INTC | G50: USD | H50: 44086 | I50: 498428 | J50: =H50/I50 -> 0.088450087 | K50: 0.1 | L50: =H50/(I50+H50) -> 0.081262419 | M50: 1.5 | N50: =M50/(1+(1-J50)*K50) -> 1.3746901
B51: Gloabal Foundaries Inc | E51: NASDAQ | F51: GFS | G51: USD | H51: 1147 | I51: 37220 | J51: =H51/I51 -> 0.030816765 | K51: 0.27 | L51: =H51/(I51+H51) -> 0.029895483 | M51: 1.34 | N51: =M51/(1+(1-J51)*K51) -> 1.0620764
...

Sheet Model
B1: Income Statement | G1: Actuals | P1: Forecasts | W1: Notes & References
B2: all figures in millions of New Taiwan Dollors NTD | G2: 45382 | H2: =EDATE(G2,3) -> 45473 | I2: =EDATE(H2,3) -> 45565 | J2: =EDATE(I2,3) -> 45656 | K2: =EDATE(J2,3) -> 45746 | L2: =EDATE(K2,3) -> 45838 | M2: =EDATE(L2,3) -> 45930 | N2: =EDATE(M2,3) -> 46021 | O2: =EDATE(N2,3) -> 46111 | ... T2: =EDATE(S2,3) -> 46568 | U2: Term
B4: Net Revenue | G4: 592644 | H4: 673510 | I4: 759692 | J4: 868461 | K4: 839254 | L4: 933792 | M4: 989918 | N4: 1046090 | O4: 1134103 | P4: =P161 -> 1248392.2 | Q4: =Q161 -> 1382472.3 | R4: =R161 -> 1536433 | S4: =S161 -> 1713637.5 | T4: =T161 -> 1917692.4 | U4: =U161 -> 2149498.4
B5: Cost of Revenue | G5: -278139 | H5: -315385 | I5: -320347 | J5: -356082 | K5: -345859 | L5: -386423 | M5: -401375 | N5: -394103 | O5: -382808 | P5: =P178*-1 -> -418211.4 | Q5: =Q178*-1 -> -459672.05 | R5: =R178*-1 -> -507022.89 | S5: =S178*-1 -> -561216.28 | T5: =T178*-1 -> -623250.02 | U5: =U178*-1 -> -694287.98
B6: Gross Profit | G6: 314505 | H6: 358125 | I6: 439345 | J6: 512379 | K6: 493395 | L6: 547369 | M6: 588543 | N6: 651987 | O6: 751295 | P6: =SUM(P4:P5) -> 830180.83 | Q6: =SUM(Q4:Q5) -> 922800.28 | R6: =SUM(R4:R5) -> 1029410.1 | S6: =SUM(S4:S5) -> 1152421.2 | T6: =SUM(T4:T5) -> 1294442.4 | U6: =SUM(U4:U5) -> 1455210.4
B8: Operating Expenses
B9: R&D Expenses | G9: -46109 | H9: -48058 | I9: -52783 | J9: -57232 | K9: -56547 | L9: -61280 | M9: -63743 | N9: -64857 | O9: -67757 | P9: =P180*-1 -> -74279.338 | Q9: =Q180*-1 -> -81565.868 | R9: =R180*-1 -> -89881.331 | S9: =S180*-1 -> -99390.975 | T9: =T180*-1 -> -111226.16 | U9: =U180*-1 -> -124670.91
B10: SG&A Eapenses | G10: -19248 | H10: -22238 | I10: -26295 | J10: -29108 | K10: -28639 | L10: -23228 | M10: -24022 | N10: -23333 | O10: -26249 | P10: =P179*-1 -> -28713.021 | Q10: =Q179*-1 -> -29031.919 | R10: =R179*-1 -> -30728.66 | S10: =S179*-1 -> -33415.931 | T10: =T179*-1 -> -36436.155 | U10: =U179*-1 -> -40840.469
B11: Total Operating Expenses | G11: -65357 | H11: -70296 | I11: -79078 | J11: -86340 | K11: -85186 | L11: -84508 | M11: -87765 | N11: -88190 | O11: -94006 | P11: =SUM(P9:P10) -> -102992.36 | Q11: =SUM(Q9:Q10) -> -110597.79 | R11: =SUM(R9:R10) -> -120609.99 | S11: =SUM(S9:S10) -> -132806.91 | T11: =SUM(T9:T10) -> -147662.31 | U11: =SUM(U9:U10) -> -165511.38
B13: Other operating Income and Expenses | G13: -130 | H13: -1273 | I13: 499 | J13: -326 | K13: -1128 | L13: 562 | M13: -93 | N13: 1106 | O13: 1677 | P13: 0 | Q13: 0 | R13: 0 | S13: 0 | T13: 0 | U13: 0
B15: Income from Operations | G15: 249018 | H15: 286556 | I15: 360766 | J15: 425713 | K15: 407081 | L15: 463423 | M15: 500685 | N15: 564903 | O15: 658966 | P15: =P6+P11+P13 -> 727188.47 | Q15: =Q6+Q11+Q13 -> 812202.5 | R15: =R6+R11+R13 -> 908800.13 | S15: =S6+S11+S13 -> 1019614.3 | T15: =T6+T11+T13 -> 1146780 | U15: =U6+U11+U13 -> 1289699
W16: Share of Profits and Associated | AH16: =AH17*P4 -> 1872.5883 | AI16: =AI17*Q4 -> 1935.4613 | AJ16: =AJ17*R4 -> 2151.0062 | AK16: =AK17*S4 -> 2399.0925 | AL16: =AL17*T4 -> 2493.0001 | AM16: =AM17*U4 -> 2794.3479
B17: Non operating Income and Expenses | W17: Share of Profit as % Rev | Y17: =G18/G4 -> 0.0014814965 | Z17: =H18/H4 -> 0.0017104423 | AA17: =I18/I4 -> 0.0020547801 | AB17: =J18/J4 -> 0.0014842348 | AC17: =K18/K4 -> 0.001630019 | AD17: =L18/L4 -> 0.0013086426 | AE17: =M18/M4 -> 0.001438503 | AF17: =N18/N4 -> 0.00141766 | AG17: =O18/O4 -> 0.0014857557 | AH17: 0.0015 | AI17: 0.0014 | AJ17: 0.0014 | AK17: 0.0014 | AL17: 0.0013 | AM17: 0.0013
B18: Share of Profits and Associated | G18: 878 | H18: 1152 | I18: 1561 | J18: 1289 | K18: 1368 | L18: 1222 | M18: 1424 | N18: 1483 | O18: 1685 | P18: =AH16 -> 1872.5883 | Q18: =AI16 -> 1935.4613 | R18: =AJ16 -> 2151.0062 | S18: =AK16 -> 2399.0925 | T18: =AL16 -> 2493.0001 | U18: =AM16 -> 2794.3479
B19: Net interest Income (Expenses) | G19: 16661 | H19: 18341 | I19: 19966 | J19: 21750 | K19: 22182 | L19: 21501 | M19: 23222 | N19: 26463 | O19: 26146 | P19: =P424 -> 26769.667 | Q19: =Q424 -> 30552.204 | R19: =R424 -> 34450.595 | S19: =S424 -> 38634.096 | T19: =T424 -> 42747.068 | U19: =U424 -> 51589.506 | W19: Net interest Income (Expenses) | AH19: =P4*AH20 -> 29961.414 | AI19: =Q4*AI20 -> 34561.808 | AJ19: =R4*AJ20 -> 39947.258 | AK19: =S4*AK20 -> 46268.212 | AL19: =T4*AL20 -> 53695.387 | AM19: =U4*AM20 -> 62335.453
B20: Other gains and Losses | G20: -14 | H20: 262 | I20: 1894 | J20: 46 | K20: 264 | L20: 6890 | M20: 38 | N20: -486 | O20: 1003 | P20: 0 | Q20: 0 | R20: 0 | S20: 0 | T20: 0 | U20: 0 | W20: interest income as % of rev | Y20: =G19/G4 -> 0.028112999 | Z20: =H19/H4 -> 0.027231964 | AA20: =I19/I4 -> 0.026281704 | AB20: =J19/J4 -> 0.025044303 | AC20: =K19/K4 -> 0.026430616 | AD20: =L19/L4 -> 0.02302547 | AE20: =M19/M4 -> 0.023458509 | AF20: =N19/N4 -> 0.025297059 | AG20: =O19/O4 -> 0.023054343 | AH20: 0.024 | AI20: 0.025 | AJ20: 0.026 | AK20: 0.027 | AL20: 0.028 | AM20: 0.029
B21: Total Non Operating Income and Expenses | G21: 17525 | H21: 19755 | I21: 23421 | J21: 23085 | K21: 23814 | L21: 29613 | M21: 24684 | N21: 27460 | O21: 28834 | P21: =SUM(P18:P20) -> 28642.255 | Q21: =SUM(Q18:Q20) -> 32487.665 | R21: =SUM(R18:R20) -> 36601.601 | S21: =SUM(S18:S20) -> 41033.189 | T21: =SUM(T18:T20) -> 45240.068 | U21: =SUM(U18:U20) -> 54383.854 | W21: interst income as % of Cash and equivalents | Y21: =G19/G83 -> 0.0098109994 | Z21: =H19/H83 -> 0.010194389 | AA21: =I19/I83 -> 0.010582044 | AB21: =J19/J83 -> 0.010222657 | AC21: =K19/K83 -> 0.0092625534 | AD21: =L19/L83 -> 0.0090931621 | AE21: =M19/M83 -> 0.0093987313 | AF21: =N19/N83 -> 0.0095608298 | ... AL21: =T19/T83 -> 0.0082860006
B23: Income before Income Taxes | G23: 266543 | H23: 306311 | I23: 384187 | J23: 448798 | K23: 430895 | L23: 493036 | M23: 525369 | N23: 592363 | O23: 687800 | P23: =P15+P21 -> 755830.73 | Q23: =Q15+Q21 -> 844690.16 | R23: =R15+R21 -> 945401.73 | S23: =S15+S21 -> 1060647.5 | T23: =T15+T21 -> 1192020.1 | U23: =U15+U21 -> 1344082.9
B25: Income Tax Expenses | G25: -41322 | H25: -58649 | I25: -59107 | J25: -74329 | K25: -70162 | L25: -95543 | M25: -73614 | N25: -86947 | O25: -114999 | P25: =P316*-1 -> -120932.92 | Q25: =Q316*-1 -> -135150.43 | R25: =R316*-1 -> -151264.28 | S25: =S316*-1 -> -169703.6 | T25: =T316*-1 -> -190723.22 | U25: =U316*-1 -> -215053.26
B27: Net Income | G27: 225221 | H27: 247662 | I27: 325080 | J27: 374469 | K27: 360733 | L27: 397493 | M27: 451755 | N27: 505416 | O27: 572480 | P27: =P23+P25 -> 634897.81 | Q27: =Q23+Q25 -> 709539.74 | R27: =R23+R25 -> 794137.45 | S27: =S23+S25 -> 890943.9 | T27: =T23+T25 -> 1001296.9 | U27: =U23+U25 -> 1129029.6
B29: Other Comprehesive Income (Losses) | G29: 41274 | H29: 13464 | I29: -21056 | J29: 37903 | K29: 31897 | L29: -254502 | M29: 95202 | N29: 71076 | O29: 53996 | P29: 40470 | Q29: 40470 | R29: 40470 | S29: 40470 | T29: 40470 | U29: 40470
B30: Comprehensive Income | G30: 266495 | H30: 261126 | I30: 304024 | J30: 412372 | K30: 392630 | L30: 142991 | M30: 546957 | N30: 576492 | O30: 626797 | P30: =P27+P29 -> 675367.81 | Q30: =Q27+Q29 -> 750009.74 | R30: =R27+R29 -> 834607.45 | S30: =S27+S29 -> 931413.9 | T30: =T27+T29 -> 1041766.9 | U30: =U27+U29 -> 1169499.6
B32: net income (losses) attributable to shareholder of the parent | G32: 225485 | H32: 247845 | I32: 325258 | J32: 374680 | K32: 361564 | L32: 398273 | M32: 452302 | N32: 505744 | O32: 572160 | P32: =P34-P33 -> 635231.81 | Q32: =Q34-Q33 -> 709873.74 | R32: =R34-R33 -> 794471.45 | S32: =S34-S33 -> 891277.9 | T32: =T34-T33 -> 1001630.9 | U32: =U34-U33 -> 1129363.6
B33: NCI | G33: -264 | H33: -183 | I33: -178 | J33: -211 | K33: -831 | L33: -780 | M33: -547 | N33: -328 | O33: 320 | P33: -334 | Q33: -334 | R33: -334 | S33: -334 | T33: -334 | U33: -334
G34: 225221 | H34: 247662 | I34: 325080 | J34: 374469 | K34: 360733 | L34: 397493 | M34: 451755 | N34: 505416 | O34: 572480 | P34: =P27 -> 634897.81 | Q34: =Q27 -> 709539.74 | R34: =R27 -> 794137.45 | S34: =S27 -> 890943.9 | T34: =T27 -> 1001296.9 | U34: =U27 -> 1129029.6
B36: Cash flow Statement
B37: all figures in millions of New Taiwan Dollors NTD | G37: =G2 -> 45382 | H37: =H2 -> 45473 | I37: =I2 -> 45565 | J37: =J2 -> 45656 | K37: =K2 -> 45746 | L37: =L2 -> 45838 | M37: =M2 -> 45930 | N37: =N2 -> 46021 | ... U37: =U2 -> Term
B39: Cash from Operating Activities
B40: Income Before Income Tax | G40: 266543 | H40: 306311 | I40: 384187 | J40: 448798 | K40: 430895 | L40: 493036 | M40: 525369 | N40: 592363 | O40: 687800 | P40: =P23 -> 755830.73 | Q40: =Q23 -> 844690.16 | R40: =R23 -> 945401.73 | S40: =S23 -> 1060647.5 | T40: =T23 -> 1192020.1
B41: D&A | G41: 159023 | H41: 165166 | I41: 168229 | J41: 170378 | K41: 175139 | L41: 188058 | M41: 162787 | N41: 162112 | O41: 165450 | P41: =P241 -> 176696.25 | Q41: =Q241 -> 185192.7 | R41: =R241 -> 194475.31 | S41: =S241 -> 204650.03 | T41: =T241 -> 215836.57
B42: Share of Profits of Associates | G42: -878 | H42: -1152 | I42: -1561 | J42: -1289 | K42: -1368 | L42: -1222 | M42: -1424 | N42: -1483 | O42: -1685 | P42: =P18*-1 -> -1872.5883 | Q42: =Q18*-1 -> -1935.4613 | R42: =R18*-1 -> -2151.0062 | S42: =S18*-1 -> -2399.0925 | T42: =T18*-1 -> -2493.0001
B43: Income Taxes Paid | G43: -1051 | H43: -88103 | I43: -93295 | J43: -1190 | K43: -1537 | L43: -127347 | M43: -137266 | N43: -1407 | O43: -1501 | P43: =P25-O25 -> -5933.9167 | Q43: =Q25-P25 -> -14217.509 | R43: =R25-Q25 -> -16113.85 | S43: =S25-R25 -> -18439.324 | T43: =T25-S25 -> -21019.617
B44: changes in working Capital & Others | G44: 12674 | H44: -4554 | I44: -65567 | J44: 3508 | K44: 22445 | L44: -55461 | M44: -122637 | N44: -26076 | O44: -151088 | P44: =P205 -> -33750.746 | Q44: =Q205 -> -70992.409 | R44: =R205 -> -77642.57 | S44: =S205 -> -81694.028 | T44: =T205 -> -71700.013
B45: Net Cash from Operating Activities | G45: 436311 | H45: 377668 | I45: 391993 | J45: 620205 | K45: 625574 | L45: 497064 | M45: 426829 | N45: 725509 | O45: 689976 | P45: =SUM(P40:P44) -> 890969.73 | Q45: =SUM(Q40:Q44) -> 942737.48 | R45: =SUM(R40:R44) -> 1043969.6 | S45: =SUM(S40:S44) -> 1162765.1 | T45: =SUM(T40:T44) -> 1312644.1
B47: Cash Flow From Investing Activities
B48: Interest Received | G48: 17410 | H48: 19195 | I48: 21356 | J48: 18473 | K48: 24419 | L48: 26025 | M48: 22351 | N48: 26160 | O48: 26746 | P48: =P19 -> 26769.667 | Q48: =Q19 -> 30552.204 | R48: =R19 -> 34450.595 | S48: =S19 -> 38634.096 | T48: =T19 -> 42747.068 | AI48: =Q47 -> 0 | AJ48: =R47 -> 0 | AK48: =S47 -> 0 | AL48: =T47 -> 0
B49: Cash Dividend Received | G49: 90 | H49: 805 | I49: 2405 | J49: 207 | K49: 95 | L49: 1091 | M49: 2705 | N49: 49 | O49: 1041 | P49: =AVERAGE(G49:O49) -> 943.11111 | Q49: =AVERAGE(H49:P49) -> 1037.9012 | R49: =AVERAGE(I49:Q49) -> 1063.7791 | S49: =AVERAGE(J49:R49) -> 914.75461 | T49: =AVERAGE(K49:S49) -> 993.39401 | U49: << | W49: Assumed as average of previous 9 quarters | Y49: =G56 -> -763 | Z49: =H56 -> 6673 | AA49: =I56 -> 7446 | AB49: =J56 -> 51560 | AC49: =K56 -> 32808 | AD49: =L56 -> 29749 | AE49: =M56 -> 3823 | AF49: =N56 -> -4939 | AG49: =O56 -> -5375 | AH49: =AH50*P4 -> 18726.343 | AI49: =AI50*Q4 -> 12642.611 | AJ49: =AJ50*R4 -> 29557.726 | AK49: =AK50*S4 -> 25380.726 | AL49: =AL50*T4 -> 35478.187
B50: Acquisitions of : | Y50: =Y49/G4 -> -0.0012874508 | Z50: =Z49/H4 -> 0.0099077965 | AA50: =AA49/I4 -> 0.0098013405 | AB50: =AB49/J4 -> 0.05936939 | AC50: =AC49/K4 -> 0.03909186 | AD50: =AD49/L4 -> 0.031858273 | AE50: =AE49/M4 -> 0.003861936 | AF50: =AF49/N4 -> -0.0047213911 | AG50: =AG49/O4 -> -0.0047394284 | AH50: 0.015000368 | AI50: 0.0091449287 | AJ50: 0.019237888 | AK50: 0.014811024 | AL50: 0.018500458
B51: PPE | G51: -181305 | H51: -205674 | I51: -207079 | J51: -361949 | K51: -330827 | L51: -297226 | M51: -287452 | N51: -356906 | O51: -350763 | P51: =P212*-1 -> -374517.67 | Q51: =Q212*-1 -> -407829.34 | R51: =R212*-1 -> -445565.57 | S51: =S212*-1 -> -488386.69 | T51: =T212*-1 -> -536953.87
B52: Marketable Financial Instruments | G52: -45800 | H52: -63263 | I52: -54209 | J52: -77351 | K52: -70741 | L52: -61989 | M52: -50445 | N52: -72197 | O52: -91621 | P52: -96235 | Q52: -74239 | R52: -85734 | S52: -82749 | T52: -59827 | U52: << | W52: Marketable Fin instrumenst acquisition is xtimes of disposals assumed to increase. From 1.3 to 1.4 from previous years
...

Sheet Key Ratios & Metrics
B2: Profitability and Return Ratios | E2: Note: All The Ratios In Bold Are Relevant & Important For The Analysis
B3: all figures in millions of New Taiwan Dollors NTD
F4: =Historicals!C2 -> 45352 | G4: =Historicals!D2 -> 45473 | H4: =Historicals!E2 -> 45565 | I4: =Historicals!F2 -> 45657 | J4: =Historicals!G2 -> 45747 | K4: =Historicals!H2 -> 45838 | L4: =Historicals!I2 -> 45930 | M4: =Historicals!J2 -> 46022 | N4: =Historicals!K2 -> 46112 | P4: =F4 -> 45352 | Q4: =G4 -> 45473 | R4: =H4 -> 45565 | S4: =I4 -> 45657 | T4: =J4 -> 45747 | U4: =K4 -> 45838 | V4: =L4 -> 45930 | W4: =M4 -> 46022 | X4: =N4 -> 46112
B7: Return on Equity | C7: = | D7: Net Income | E7: = | F7: =Historicals!C27 -> 225221 | G7: =Historicals!D27 -> 247662 | H7: =Historicals!E27 -> 325080 | I7: =Historicals!F27 -> 374469 | J7: =Historicals!G27 -> 360733 | K7: =Historicals!H27 -> 397493 | L7: =Historicals!I27 -> 451755 | M7: =Historicals!J27 -> 505416 | N7: =Historicals!K27 -> 572480 | O7: = | P7: =IF(F8=0,,F7/F8) -> 0.061946535 | Q7: =IF(G8=0,,G7/G8) -> 0.065321993 | R7: =IF(H8=0,,H7/H8) -> 0.081473296 | S7: =IF(I8=0,,I7/I8) -> 0.087318426 | T7: =IF(J8=0,,J7/J8) -> 0.079035976 | U7: =IF(K8=0,,K7/K8) -> 0.086768518 | V7: =IF(L8=0,,L7/L8) -> 0.090381603 | W7: =IF(M8=0,,M7/M8) -> 0.093257136 | X7: =IF(N8=0,,N7/N8) -> 0.097179407
D8: Equity | F8: =Historicals!C122 -> 3635732 | G8: =Historicals!D122 -> 3791403 | H8: =Historicals!E122 -> 3990019 | I8: =Historicals!F122 -> 4288545 | J8: =Historicals!G122 -> 4564162 | K8: =Historicals!H122 -> 4581074 | L8: =Historicals!I122 -> 4998307 | M8: =Historicals!J122 -> 5419596 | N8: =Historicals!K122 -> 5890960
B10: Return on Assets | C10: = | D10: Net Income | E10: = | F10: =+F7 -> 225221 | G10: =+G7 -> 247662 | H10: =+H7 -> 325080 | I10: =+I7 -> 374469 | J10: =+J7 -> 360733 | K10: =+K7 -> 397493 | L10: =+L7 -> 451755 | M10: =+M7 -> 505416 | N10: =+N7 -> 572480 | O10: = | P10: =IF(F11=0,,F10/F11) -> 0.038912447 | Q10: =IF(G11=0,,G10/G11) -> 0.041398685 | R10: =IF(H11=0,,H10/H11) -> 0.0527243 | S10: =IF(I11=0,,I10/I11) -> 0.055958229 | T10: =IF(J11=0,,J10/J11) -> 0.050570375 | U10: =IF(K11=0,,K10/K11) -> 0.056733249 | V10: =IF(L11=0,,L10/L11) -> 0.06142894 | W10: =IF(M11=0,,M10/M11) -> 0.063710383 | X10: =IF(N11=0,,N10/N11) -> 0.066098985
D11: Total Assets | F11: =Historicals!C96 -> 5787891 | G11: =Historicals!D96 -> 5982364 | H11: =Historicals!E96 -> 6165658 | I11: =Historicals!F96 -> 6691938 | J11: =Historicals!G96 -> 7133287 | K11: =Historicals!H96 -> 7006350 | L11: =Historicals!I96 -> 7354107 | M11: =Historicals!J96 -> 7933024 | N11: =Historicals!K96 -> 8660950
B13: Return on Net Assets | C13: = | D13: Net Income | E13: = | F13: =F10 -> 225221 | G13: =G10 -> 247662 | H13: =H10 -> 325080 | I13: =I10 -> 374469 | J13: =J10 -> 360733 | K13: =K10 -> 397493 | L13: =L10 -> 451755 | M13: =M10 -> 505416 | N13: =N10 -> 572480 | O13: = | P13: =IF(F14=0,,F13/F14) -> 0.05767642 | Q13: =IF(G14=0,,G13/G14) -> 0.062186852 | R13: =IF(H14=0,,H13/H14) -> 0.079619391 | S13: =IF(I14=0,,I13/I14) -> 0.087137509 | T13: =IF(J14=0,,J13/J14) -> 0.080835766 | U13: =IF(K14=0,,K13/K14) -> 0.090428966 | V13: =IF(L14=0,,L13/L14) -> 0.097750053 | W13: =IF(M14=0,,M13/M14) -> 0.10308074 | X13: =IF(N14=0,,N13/N14) -> 0.10839283
D14: PP&E plus Net Working Capital | F14: =Historicals!C153 -> 3904906 | G14: =Historicals!D153 -> 3982546 | H14: =Historicals!E153 -> 4082925 | I14: =Historicals!F153 -> 4297449 | J14: =Historicals!G153 -> 4462542 | K14: =Historicals!H153 -> 4395638 | L14: =Historicals!I153 -> 4621532 | M14: =Historicals!J153 -> 4903108 | N14: =Historicals!K153 -> 5281530
B16: Return on Invested Capital | C16: = | D16: NOPAT | E16: = | F16: =Historicals!C137 -> 210412.89 | G16: =Historicals!D137 -> 231689.47 | H16: =Historicals!E137 -> 305262.31 | I16: =Historicals!F137 -> 355207.29 | J16: =Historicals!G137 -> 340796.6 | K16: =Historicals!H137 -> 373618.56 | L16: =Historicals!I137 -> 430529.69 | M16: =Historicals!J137 -> 481986.58 | N16: =Historicals!K137 -> 548788 | O16: = | P16: =IF(F17=0,,F16/F17) -> 0.071433429 | Q16: =IF(G17=0,,G16/G17) -> 0.076757997 | R16: =IF(H17=0,,H16/H17) -> 0.097524477 | S16: =IF(I17=0,,I16/I17) -> 0.11051067 | T16: =IF(J17=0,,J16/J17) -> 0.10468089 | U16: =IF(K17=0,,K16/K17) -> 0.11567163 | V16: =IF(L17=0,,L16/L17) -> 0.12095999 | W16: =IF(M17=0,,M16/M17) -> 0.12936016 | X16: =IF(N17=0,,N16/N17) -> 0.13879271
D17: Invested Capital | F17: =Historicals!C146 -> 2945580.1 | G17: =Historicals!D146 -> 3018440.8 | H17: =Historicals!E146 -> 3130109.7 | I17: =Historicals!F146 -> 3214235.4 | J17: =Historicals!G146 -> 3255575.9 | K17: =Historicals!H146 -> 3229993 | L17: =Historicals!I146 -> 3559273.5 | M17: =Historicals!J146 -> 3725927.5 | N17: =Historicals!K146 -> 3954011.7
B19: Gross Margin | C19: = | D19: Gross Profit | E19: = | F19: =Historicals!C6 -> 314505 | G19: =Historicals!D6 -> 358125 | H19: =Historicals!E6 -> 439345 | I19: =Historicals!F6 -> 512379 | J19: =Historicals!G6 -> 493395 | K19: =Historicals!H6 -> 547369 | L19: =Historicals!I6 -> 588543 | M19: =Historicals!J6 -> 651987 | N19: =Historicals!K6 -> 751295 | O19: = | P19: =IF(F20=0,,F19/F20) -> 0.53068115 | Q19: =IF(G20=0,,G19/G20) -> 0.5317293 | R19: =IF(H20=0,,H19/H20) -> 0.5783199 | S19: =IF(I20=0,,I19/I20) -> 0.58998504 | T19: =IF(J20=0,,J19/J20) -> 0.58789711 | U19: =IF(K20=0,,K19/K20) -> 0.58617872 | V19: =IF(L20=0,,L19/L20) -> 0.59453712 | W19: =IF(M20=0,,M19/M20) -> 0.6232609 | X19: =IF(N20=0,,N19/N20) -> 0.66245747
D20: =+D29 -> Revenue | F20: =Historicals!C4 -> 592644 | G20: =Historicals!D4 -> 673510 | H20: =Historicals!E4 -> 759692 | I20: =Historicals!F4 -> 868461 | J20: =Historicals!G4 -> 839254 | K20: =Historicals!H4 -> 933792 | L20: =Historicals!I4 -> 989918 | M20: =Historicals!J4 -> 1046090 | N20: =Historicals!K4 -> 1134103
B22: R&D% of Revenue | C22: = | D22: R&D | E22: = | F22: =Historicals!C9*-1 -> 46109 | G22: =Historicals!D9*-1 -> 48058 | H22: =Historicals!E9*-1 -> 52783 | I22: =Historicals!F9*-1 -> 57232 | J22: =Historicals!G9*-1 -> 56547 | K22: =Historicals!H9*-1 -> 61280 | L22: =Historicals!I9*-1 -> 63743 | M22: =Historicals!J9*-1 -> 64857 | N22: =Historicals!K9*-1 -> 67757 | O22: = | P22: =IF(F23=0,,F22/F23) -> 0.077802188 | Q22: =IF(G23=0,,G22/G23) -> 0.071354546 | R22: =IF(H23=0,,H22/H23) -> 0.069479473 | S22: =IF(I23=0,,I22/I23) -> 0.065900484 | T22: =IF(J23=0,,J22/J23) -> 0.067377695 | U22: =IF(K23=0,,K22/K23) -> 0.065624893 | V22: =IF(L23=0,,L22/L23) -> 0.064392202 | W22: =IF(M23=0,,M22/M23) -> 0.061999446 | X22: =IF(N23=0,,N22/N23) -> 0.059745014
D23: =+D20 -> Revenue | F23: =F20 -> 592644 | G23: =G20 -> 673510 | H23: =H20 -> 759692 | I23: =I20 -> 868461 | J23: =J20 -> 839254 | K23: =K20 -> 933792 | L23: =L20 -> 989918 | M23: =M20 -> 1046090 | N23: =N20 -> 1134103
B25: Cash to Revenue | C25: = | D25: Cash | E25: = | F25: =Historicals!C150*-1 -> 1698196 | G25: =Historicals!D150*-1 -> 1799127 | H25: =Historicals!E150*-1 -> 1886781 | I25: =Historicals!F150*-1 -> 2127627 | J25: =Historicals!G150*-1 -> 2394804 | K25: =Historicals!H150*-1 -> 2364524 | L25: =Historicals!I150*-1 -> 2470759 | M25: =Historicals!J150*-1 -> 2767856 | N25: =Historicals!K150*-1 -> 3035637 | O25: = | P25: =IF(F26=0,,F25/F26) -> 2.8654572 | Q25: =IF(G26=0,,G25/G26) -> 2.6712699 | R25: =IF(H26=0,,H25/H26) -> 2.4836131 | S25: =IF(I26=0,,I25/I26) -> 2.449882 | T25: =IF(J26=0,,J25/J26) -> 2.8534913 | U25: =IF(K26=0,,K25/K26) -> 2.5321742 | V25: =IF(L26=0,,L25/L26) -> 2.4959229 | W25: =IF(M26=0,,M25/M26) -> 2.6459062 | X25: =IF(N26=0,,N25/N26) -> 2.6766855
D26: =+D23 -> Revenue | F26: =F23 -> 592644 | G26: =G23 -> 673510 | H26: =H23 -> 759692 | I26: =I23 -> 868461 | J26: =J23 -> 839254 | K26: =K23 -> 933792 | L26: =L23 -> 989918 | M26: =M23 -> 1046090 | N26: =N23 -> 1134103
B28: FCF Margin | C28: = | D28: FCF | E28: = | F28: =Historicals!C162 -> 172740 | G28: =Historicals!D162 -> 191953 | H28: =Historicals!E162 -> 328376 | I28: =Historicals!F162 -> 156305 | J28: =Historicals!G162 -> 158786 | K28: =Historicals!H162 -> 314173 | L28: =Historicals!I162 -> 425043 | M28: =Historicals!J162 -> 309238 | N28: =Historicals!K162 -> 509742 | O28: = | P28: =IF(F29=0,,F28/F29) -> 0.29147346 | Q28: =IF(G29=0,,G28/G29) -> 0.28500393 | R28: =IF(H29=0,,H28/H29) -> 0.43224886 | S28: =IF(I29=0,,I28/I29) -> 0.1799793 | T28: =IF(J29=0,,J28/J29) -> 0.18919898 | U28: =IF(K29=0,,K28/K29) -> 0.33644859 | V28: =IF(L29=0,,L28/L29) -> 0.42937193 | W28: =IF(M29=0,,M28/M29) -> 0.29561319 | X28: =IF(N29=0,,N28/N29) -> 0.44946711
D29: =+D35 -> Revenue | F29: =F26 -> 592644 | G29: =G26 -> 673510 | H29: =H26 -> 759692 | I29: =I26 -> 868461 | J29: =J26 -> 839254 | K29: =K26 -> 933792 | L29: =L26 -> 989918 | M29: =M26 -> 1046090 | N29: =N26 -> 1134103
B31: Depreciation % of Revenue | C31: = | D31: Depreciation | E31: = | F31: =Historicals!C41 -> 159023 | G31: =Historicals!D41 -> 165166 | H31: =Historicals!E41 -> 168229 | I31: =Historicals!F41 -> 170378 | J31: =Historicals!G41 -> 175139 | K31: =Historicals!H41 -> 188058 | L31: =Historicals!I41 -> 162787 | M31: =Historicals!J41 -> 162112 | N31: =Historicals!K41 -> 165450 | O31: = | P31: =IF(F32=0,,F31/F32) -> 0.26832804 | Q31: =IF(G32=0,,G31/G32) -> 0.2452317 | R31: =IF(H32=0,,H31/H32) -> 0.22144369 | S31: =IF(I32=0,,I31/I32) -> 0.19618382 | T31: =IF(J32=0,,J31/J32) -> 0.20868414 | U31: =IF(K32=0,,K31/K32) -> 0.20139174 | V31: =IF(L32=0,,L31/L32) -> 0.16444493 | W31: =IF(M32=0,,M31/M32) -> 0.15496946 | X31: =IF(N32=0,,N31/N32) -> 0.14588622
D32: =+D20 -> Revenue | F32: =F29 -> 592644 | G32: =G29 -> 673510 | H32: =H29 -> 759692 | I32: =I29 -> 868461 | J32: =J29 -> 839254 | K32: =K29 -> 933792 | L32: =L29 -> 989918 | M32: =M29 -> 1046090 | N32: =N29 -> 1134103
B34: Operating Margin | C34: = | D34: EBIT | E34: = | F34: =Historicals!C15 -> 249018 | G34: =Historicals!D15 -> 286556 | H34: =Historicals!E15 -> 360766 | I34: =Historicals!F15 -> 425713 | J34: =Historicals!G15 -> 407081 | K34: =Historicals!H15 -> 463423 | L34: =Historicals!I15 -> 500685 | M34: =Historicals!J15 -> 564903 | N34: =Historicals!K15 -> 658966 | O34: = | P34: =IF(F35=0,,F34/F35) -> 0.42018142 | Q34: =IF(G35=0,,G34/G35) -> 0.42546659 | R34: =IF(H35=0,,H34/H35) -> 0.47488456 | S34: =IF(I35=0,,I34/I35) -> 0.49019242 | T34: =IF(J35=0,,J34/J35) -> 0.48505101 | U34: =IF(K35=0,,K34/K35) -> 0.49628076 | V34: =IF(L35=0,,L34/L35) -> 0.50578432 | W34: =IF(M35=0,,M34/M35) -> 0.54001377 | X34: =IF(N35=0,,N34/N35) -> 0.58104599
D35: =+D41 -> Revenue | F35: =F32 -> 592644 | G35: =G32 -> 673510 | H35: =H32 -> 759692 | I35: =I32 -> 868461 | J35: =J32 -> 839254 | K35: =K32 -> 933792 | L35: =L32 -> 989918 | M35: =M32 -> 1046090 | N35: =N32 -> 1134103
B37: Net Cash % of Revenue | C37: = | D37: Net Cash | E37: = | F37: ='Key Ratios & Metrics'!F79-'Key Ratios & Metrics'!F119 -> 720135.87 | G37: ='Key Ratios & Metrics'!G79-'Key Ratios & Metrics'!G119 -> 801707.23 | H37: ='Key Ratios & Metrics'!H79-'Key Ratios & Metrics'!H119 -> 891812.32 | I37: ='Key Ratios & Metrics'!I79-'Key Ratios & Metrics'!I119 -> 1109340.6 | J37: ='Key Ratios & Metrics'!J79-'Key Ratios & Metrics'!J119 -> 1346048.1 | K37: ='Key Ratios & Metrics'!K79-'Key Ratios & Metrics'!K119 -> 1386639 | L37: ='Key Ratios & Metrics'!L79-'Key Ratios & Metrics'!L119 -> 1476304.5 | M37: ='Key Ratios & Metrics'!M79-'Key Ratios & Metrics'!M119 -> 1734867.5 | N37: ='Key Ratios & Metrics'!N79-'Key Ratios & Metrics'!N119 -> 1978377.3 | O37: = | P37: =IF(F38=0,,F37/F38) -> 1.2151239 | Q37: =IF(G38=0,,G37/G38) -> 1.190342 | R37: =IF(H38=0,,H37/H38) -> 1.173913 | S37: =IF(I38=0,,I37/I38) -> 1.2773638 | T37: =IF(J38=0,,J37/J38) -> 1.6038626 | U37: =IF(K38=0,,K37/K38) -> 1.4849549 | V37: =IF(L38=0,,L37/L38) -> 1.4913402 | W37: =IF(M38=0,,M37/M38) -> 1.6584304 | X37: =IF(N38=0,,N37/N38) -> 1.7444424
D38: =+D35 -> Revenue | F38: =F35 -> 592644 | G38: =G35 -> 673510 | H38: =H35 -> 759692 | I38: =I35 -> 868461 | J38: =J35 -> 839254 | K38: =K35 -> 933792 | L38: =L35 -> 989918 | M38: =M35 -> 1046090 | N38: =N35 -> 1134103
B40: EBT Margin | C40: = | D40: Earning Before Tax | E40: = | F40: =Historicals!C23 -> 266543 | G40: =Historicals!D23 -> 306311 | H40: =Historicals!E23 -> 384187 | I40: =Historicals!F23 -> 448798 | J40: =Historicals!G23 -> 430895 | K40: =Historicals!H23 -> 493036 | L40: =Historicals!I23 -> 525369 | M40: =Historicals!J23 -> 592363 | N40: =Historicals!K23 -> 687800 | O40: = | P40: =IF(F41=0,,F40/F41) -> 0.4497523 | Q40: =IF(G41=0,,G40/G41) -> 0.454798 | R40: =IF(H41=0,,H40/H41) -> 0.50571416 | S40: =IF(I41=0,,I40/I41) -> 0.51677393 | T40: =IF(J41=0,,J40/J41) -> 0.51342621 | U40: =IF(K41=0,,K40/K41) -> 0.52799339 | V40: =IF(L41=0,,L40/L41) -> 0.53071972 | W40: =IF(M41=0,,M40/M41) -> 0.5662639 | X40: =IF(N41=0,,N40/N41) -> 0.60647049
D41: =+D47 -> Revenue | F41: =F38 -> 592644 | G41: =G38 -> 673510 | H41: =H38 -> 759692 | I41: =I38 -> 868461 | J41: =J38 -> 839254 | K41: =K38 -> 933792 | L41: =L38 -> 989918 | M41: =M38 -> 1046090 | N41: =N38 -> 1134103
B43: Tax % of Revenue | C43: = | D43: Tax | E43: = | F43: =Historicals!C25*-1 -> 41322 | G43: =Historicals!D25*-1 -> 58649 | H43: =Historicals!E25*-1 -> 59107 | I43: =Historicals!F25*-1 -> 74329 | J43: =Historicals!G25*-1 -> 70162 | K43: =Historicals!H25*-1 -> 95543 | L43: =Historicals!I25*-1 -> 73614 | M43: =Historicals!J25*-1 -> 86947 | N43: =Historicals!K25*-1 -> 114999 | O43: = | P43: =IF(F44=0,,F43/F44) -> 0.069724826 | Q43: =IF(G44=0,,G43/G44) -> 0.087079628 | R43: =IF(H44=0,,H43/H44) -> 0.077803899 | S43: =IF(I44=0,,I43/I44) -> 0.085587033 | T43: =IF(J44=0,,J43/J44) -> 0.083600436 | U43: =IF(K44=0,,K43/K44) -> 0.10231722 | V43: =IF(L44=0,,L43/L44) -> 0.074363735 | W43: =IF(M44=0,,M43/M44) -> 0.083116175 | X43: =IF(N44=0,,N43/N44) -> 0.10140084
D44: =+D20 -> Revenue | F44: =F41 -> 592644 | G44: =G41 -> 673510 | H44: =H41 -> 759692 | I44: =I41 -> 868461 | J44: =J41 -> 839254 | K44: =K41 -> 933792 | L44: =L41 -> 989918 | M44: =M41 -> 1046090 | N44: =N41 -> 1134103
B46: Net Profit Margin | C46: = | D46: =D10 -> Net Income | E46: = | F46: =Historicals!C27 -> 225221 | G46: =Historicals!D27 -> 247662 | H46: =Historicals!E27 -> 325080 | I46: =Historicals!F27 -> 374469 | J46: =Historicals!G27 -> 360733 | K46: =Historicals!H27 -> 397493 | L46: =Historicals!I27 -> 451755 | M46: =Historicals!J27 -> 505416 | N46: =Historicals!K27 -> 572480 | O46: = | P46: =IF(F47=0,,F46/F47) -> 0.38002747 | Q46: =IF(G47=0,,G46/G47) -> 0.36771837 | R46: =IF(H47=0,,H46/H47) -> 0.42791026 | S46: =IF(I47=0,,I46/I47) -> 0.43118689 | T46: =IF(J47=0,,J46/J47) -> 0.42982577 | U46: =IF(K47=0,,K46/K47) -> 0.42567617 | V46: =IF(L47=0,,L46/L47) -> 0.45635598 | W46: =IF(M47=0,,M46/M47) -> 0.48314772 | X46: =IF(N47=0,,N46/N47) -> 0.5047866
D47: Revenue | F47: =F44 -> 592644 | G47: =G44 -> 673510 | H47: =H44 -> 759692 | I47: =I44 -> 868461 | J47: =J44 -> 839254 | K47: =K44 -> 933792 | L47: =L44 -> 989918 | M47: =M44 -> 1046090 | N47: =N44 -> 1134103
B49: Effective Tax Rate | C49: = | D49: Tax | E49: = | F49: =F43 -> 41322 | G49: =G43 -> 58649 | H49: =H43 -> 59107 | I49: =I43 -> 74329 | J49: =J43 -> 70162 | K49: =K43 -> 95543 | L49: =L43 -> 73614 | M49: =M43 -> 86947 | N49: =N43 -> 114999 | O49: = | P49: =IF(F50=0,,F49/F50) -> 0.15502939 | Q49: =IF(G50=0,,G49/G50) -> 0.1914688 | R49: =IF(H50=0,,H49/H50) -> 0.15384956 | S49: =IF(I50=0,,I49/I50) -> 0.16561794 | T49: =IF(J50=0,,J49/J50) -> 0.16282853 | U49: =IF(K50=0,,K49/K50) -> 0.19378504 | V49: =IF(L50=0,,L49/L50) -> 0.14011866 | W49: =IF(M50=0,,M49/M50) -> 0.14677993 | X49: =IF(N50=0,,N49/N50) -> 0.16719831
D50: =+D40 -> Earning Before Tax | F50: =F40 -> 266543 | G50: =G40 -> 306311 | H50: =H40 -> 384187 | I50: =I40 -> 448798 | J50: =J40 -> 430895 | K50: =K40 -> 493036 | L50: =L40 -> 525369 | M50: =M40 -> 592363 | N50: =N40 -> 687800
B52: Tax Burden | C52: = | D52: Net Income | E52: = | F52: =F46 -> 225221 | G52: =G46 -> 247662 | H52: =H46 -> 325080 | I52: =I46 -> 374469 | J52: =J46 -> 360733 | K52: =K46 -> 397493 | L52: =L46 -> 451755 | M52: =M46 -> 505416 | N52: =N46 -> 572480 | O52: = | P52: =IF(F53=0,,F52/F53) -> 0.84497061 | Q52: =IF(G53=0,,G52/G53) -> 0.8085312 | R52: =IF(H53=0,,H52/H53) -> 0.84615044 | S52: =IF(I53=0,,I52/I53) -> 0.83438206 | T52: =IF(J53=0,,J52/J53) -> 0.83717147 | U52: =IF(K53=0,,K52/K53) -> 0.80621496 | V52: =IF(L53=0,,L52/L53) -> 0.85988134 | W52: =IF(M53=0,,M52/M53) -> 0.85322007 | X52: =IF(N53=0,,N52/N53) -> 0.83233498
D53: =+D50 -> Earning Before Tax | F53: =F50 -> 266543 | G53: =G50 -> 306311 | H53: =H50 -> 384187 | I53: =I50 -> 448798 | J53: =J50 -> 430895 | K53: =K50 -> 493036 | L53: =L50 -> 525369 | M53: =M50 -> 592363 | N53: =N50 -> 687800
B55: Net Interest Income % EBIT | C55: = | D55: Net Interest Income | E55: = | F55: =Historicals!C19 -> 16661 | G55: =Historicals!D19 -> 18341 | H55: =Historicals!E19 -> 19966 | I55: =Historicals!F19 -> 21750 | J55: =Historicals!G19 -> 22182 | K55: =Historicals!H19 -> 21501 | L55: =Historicals!I19 -> 23222 | M55: =Historicals!J19 -> 26463 | N55: =Historicals!K19 -> 26146 | O55: = | P55: =IF(F56=0,,F55/F56) -> 0.06690681 | Q55: =IF(G56=0,,G55/G56) -> 0.064004941 | R55: =IF(H56=0,,H55/H56) -> 0.055343353 | S55: =IF(I56=0,,I55/I56) -> 0.051090758 | T55: =IF(J56=0,,J55/J56) -> 0.054490384 | U55: =IF(K56=0,,K55/K56) -> 0.046396057 | V55: =IF(L56=0,,L55/L56) -> 0.046380459 | W55: =IF(M56=0,,M55/M56) -> 0.046845211 | X55: =IF(N56=0,,N55/N56) -> 0.039677313
D56: EBIT | F56: =F34 -> 249018 | G56: =G34 -> 286556 | H56: =H34 -> 360766 | I56: =I34 -> 425713 | J56: =J34 -> 407081 | K56: =K34 -> 463423 | L56: =L34 -> 500685 | M56: =M34 -> 564903 | N56: =N34 -> 658966
B58: CapEx % of Revenue | C58: = | D58: CapEx | E58: = | F58: =Historicals!C51*-1 -> 181305 | G58: =Historicals!D51*-1 -> 205674 | H58: =Historicals!E51*-1 -> 207079 | I58: =Historicals!F51*-1 -> 361949 | J58: =Historicals!G51*-1 -> 330827 | K58: =Historicals!H51*-1 -> 297226 | L58: =Historicals!I51*-1 -> 287452 | M58: =Historicals!J51*-1 -> 356906 | N58: =Historicals!K51*-1 -> 350763 | O58: = | P58: =IF(F59=0,,F58/F59) -> 0.30592565 | Q58: =IF(G59=0,,G58/G59) -> 0.30537631 | R58: =IF(H59=0,,H58/H59) -> 0.27258284 | S58: =IF(I59=0,,I58/I59) -> 0.41677059 | T58: =IF(J59=0,,J58/J59) -> 0.39419175 | U58: =IF(K59=0,,K58/K59) -> 0.31830001 | V58: =IF(L59=0,,L58/L59) -> 0.29037961 | W58: =IF(M59=0,,M58/M59) -> 0.34118097 | X58: =IF(N59=0,,N58/N59) -> 0.30928672
D59: Revenue | F59: =F44 -> 592644 | G59: =G44 -> 673510 | H59: =H44 -> 759692 | I59: =I44 -> 868461 | J59: =J44 -> 839254 | K59: =K44 -> 933792 | L59: =L44 -> 989918 | M59: =M44 -> 1046090 | N59: =N44 -> 1134103
B61: FCF Conversion | C61: = | D61: FCF | E61: = | F61: =F28 -> 172740 | G61: =G28 -> 191953 | H61: =H28 -> 328376 | I61: =I28 -> 156305 | J61: =J28 -> 158786 | K61: =K28 -> 314173 | L61: =L28 -> 425043 | M61: =M28 -> 309238 | N61: =N28 -> 509742 | O61: = | P61: =IF(F62=0,,F61/F62) -> 0.76697999 | Q61: =IF(G62=0,,G61/G62) -> 0.77506036 | R61: =IF(H62=0,,H61/H62) -> 1.010139 | S61: =IF(I62=0,,I61/I62) -> 0.41740438 | T61: =IF(J62=0,,J61/J62) -> 0.44017598 | U61: =IF(K62=0,,K61/K62) -> 0.79038625 | V61: =IF(L62=0,,L61/L62) -> 0.9408706 | W61: =IF(M62=0,,M61/M62) -> 0.61184846 | X61: =IF(N62=0,,N61/N62) -> 0.89041015
...

Sheet Historicals
B1: Income Statement | C1: Actuals
B2: all figures in millions of New Taiwan Dollors NTD | C2: 45352 | D2: =EOMONTH(C2,3) -> 45473 | E2: =EOMONTH(D2,3) -> 45565 | F2: =EOMONTH(E2,3) -> 45657 | G2: =EOMONTH(F2,3) -> 45747 | H2: =EOMONTH(G2,3) -> 45838 | I2: =EOMONTH(H2,3) -> 45930 | J2: =EOMONTH(I2,3) -> 46022 | K2: =EOMONTH(J2,3) -> 46112 | N2: Revenue Schedule by Technology & Platform | Q2: =Model!G2 -> 45382 | R2: =Model!H2 -> 45473 | S2: =Model!I2 -> 45565 | T2: =Model!J2 -> 45656 | U2: =Model!K2 -> 45746 | V2: =Model!L2 -> 45838 | W2: =Model!M2 -> 45930 | X2: =Model!N2 -> 46021 | Y2: =Model!O2 -> 46111
B4: Net Revenue | C4: 592644 | D4: 673510 | E4: 759692 | F4: 868461 | G4: 839254 | H4: 933792 | I4: 989918 | J4: 1046090 | K4: 1134103 | N4: Revenue by Technology
B5: Cost of Revenue | C5: -278139 | D5: -315385 | E5: -320347 | F5: -356082 | G5: -345859 | H5: -386423 | I5: -401375 | J5: -394103 | K5: -382808 | N5: 3nm | Q5: 0.09 | R5: 0.15 | S5: 0.2 | T5: 0.26 | U5: 0.22 | V5: 0.24 | W5: 0.23 | X5: 0.28 | Y5: 0.28
B6: Gross Profit | C6: 314505 | D6: 358125 | E6: 439345 | F6: 512379 | G6: 493395 | H6: 547369 | I6: 588543 | J6: 651987 | K6: 751295 | N6: 5nm | Q6: 0.37 | R6: 0.35 | S6: 0.32 | T6: 0.34 | U6: 0.36 | V6: 0.36 | W6: 0.37 | X6: 0.35 | Y6: 0.35
K7: =K15+K41 -> 824416 | N7: 7nm | Q7: 0.19 | R7: 0.17 | S7: 0.17 | T7: 0.14 | U7: 0.15 | V7: 0.14 | W7: 0.14 | X7: 0.14 | Y7: 0.14
B8: Operating Expenses | N8: 16/17nm | Q8: 0.09 | R8: 0.09 | S8: 0.08 | T8: 0.07 | U8: 0.07 | V8: 0.07 | W8: 0.07 | X8: 0.06 | Y8: 0.07
B9: R&D Expenses | C9: -46109 | D9: -48058 | E9: -52783 | F9: -57232 | G9: -56547 | H9: -61280 | I9: -63743 | J9: -64857 | K9: -67757 | N9: 28nm | Q9: 0.08 | R9: 0.08 | S9: 0.07 | T9: 0.06 | U9: 0.07 | V9: 0.07 | W9: 0.07 | X9: 0.06 | Y9: 0.05
B10: SG&A Expenses | C10: -19248 | D10: -22238 | E10: -26295 | F10: -29108 | G10: -28639 | H10: -23228 | I10: -24022 | J10: -23333 | K10: -26249 | N10: 40/45nm | Q10: 0.05 | R10: 0.05 | S10: 0.04 | T10: 0.03 | U10: 0.03 | V10: 0.03 | W10: 0.03 | X10: 0.03 | Y10: 0.03
B11: Total Operating Expenses | C11: -65357 | D11: -70296 | E11: -79078 | F11: -86340 | G11: -85186 | H11: -84508 | I11: -87765 | J11: -88190 | K11: -94006 | N11: 65nm | Q11: 0.04 | R11: 0.03 | S11: 0.04 | T11: 0.04 | U11: 0.04 | V11: 0.03 | W11: 0.04 | X11: 0.04 | Y11: 0.04
N12: 90nm | Q12: 0.01 | R12: 0.01 | S12: 0.01 | T12: 0.01 | U12: 0.01 | V12: 0.01 | W12: 0.01 | X12: 0.01 | Y12: 0.01
B13: Other operating Income and Expenses | C13: -130 | D13: -1273 | E13: 499 | F13: -326 | G13: -1128 | H13: 562 | I13: -93 | J13: 1106 | K13: 1677 | N13: 0.11/0.13um | Q13: 0.03 | R13: 0.02 | S13: 0.02 | T13: 0.02 | U13: 0.02 | V13: 0.02 | W13: 0.01 | X13: 0.01 | Y13: 0.01
N14: 0.15/0.18um | Q14: 0.04 | R14: 0.04 | S14: 0.04 | T14: 0.03 | U14: 0.03 | V14: 0.03 | W14: 0.03 | X14: 0.02 | Y14: 0.02
B15: Income from Operations | C15: 249018 | D15: 286556 | E15: 360766 | F15: 425713 | G15: 407081 | H15: 463423 | I15: 500685 | J15: 564903 | K15: 658966 | N15: 0.25um and above | Q15: 0.01 | R15: 0.01 | S15: 0.01 | T15: 0 | U15: 0 | V15: 0 | W15: 0 | X15: 0 | Y15: 0
B17: Non operating Income and Expenses | N17: Revenue by Platform
B18: Share of Profits and Associated | C18: 878 | D18: 1152 | E18: 1561 | F18: 1289 | G18: 1368 | H18: 1222 | I18: 1424 | J18: 1483 | K18: 1685 | N18: HPC | Q18: 0.46 | R18: 0.52 | S18: 0.51 | T18: 0.53 | U18: 0.59 | V18: 0.6 | W18: 0.57 | X18: 0.55 | Y18: 0.61
B19: Net interest Income (Expenses) | C19: 16661 | D19: 18341 | E19: 19966 | F19: 21750 | G19: 22182 | H19: 21501 | I19: 23222 | J19: 26463 | K19: 26146 | N19: Smartphone | Q19: 0.38 | R19: 0.33 | S19: 0.34 | T19: 0.35 | U19: 0.28 | V19: 0.27 | W19: 0.3 | X19: 0.32 | Y19: 0.26
B20: Other gains and Losses | C20: -14 | D20: 262 | E20: 1894 | F20: 46 | G20: 264 | H20: 6890 | I20: 38 | J20: -486 | K20: 1003 | N20: IoT | Q20: 0.06 | R20: 0.06 | S20: 0.07 | T20: 0.05 | U20: 0.05 | V20: 0.05 | W20: 0.05 | X20: 0.05 | Y20: 0.06
B21: Total Non Operating Income and Expenses | C21: 17525 | D21: 19755 | E21: 23421 | F21: 23085 | G21: 23814 | H21: 29613 | I21: 24684 | J21: 27460 | K21: 28834 | N21: Automotive | Q21: 0.06 | R21: 0.05 | S21: 0.05 | T21: 0.04 | U21: 0.05 | V21: 0.05 | W21: 0.05 | X21: 0.05 | Y21: 0.04
N22: DCE | Q22: 0.02 | R22: 0.02 | S22: 0.01 | T22: 0.01 | U22: 0.01 | V22: 0.01 | W22: 0.01 | X22: 0.01 | Y22: 0.01
B23: Income before Income Taxes | C23: 266543 | D23: 306311 | E23: 384187 | F23: 448798 | G23: 430895 | H23: 493036 | I23: 525369 | J23: 592363 | K23: 687800 | N23: others | Q23: 0.02 | R23: 0.02 | S23: 0.02 | T23: 0.02 | U23: 0.02 | V23: 0.02 | W23: 0.02 | X23: 0.02 | Y23: 0.02
B25: Income Tax Expenses | C25: -41322 | D25: -58649 | E25: -59107 | F25: -74329 | G25: -70162 | H25: -95543 | I25: -73614 | J25: -86947 | K25: -114999 | N25: Revenue by Platform
N26: HPC | Q26: =Q18*Model!G$4 -> 272616.24 | R26: =R18*Model!H$4 -> 350225.2 | S26: =S18*Model!I$4 -> 387442.92 | T26: =T18*Model!J$4 -> 460284.33 | U26: =U18*Model!K$4 -> 495159.86 | V26: =V18*Model!L$4 -> 560275.2 | W26: =W18*Model!M$4 -> 564253.26 | X26: =X18*Model!N$4 -> 575349.5 | Y26: =Y18*Model!O$4 -> 691802.83
B27: Net Income | C27: 225221 | D27: 247662 | E27: 325080 | F27: 374469 | G27: 360733 | H27: 397493 | I27: 451755 | J27: 505416 | K27: 572480 | N27: Smartphone | Q27: =Q19*Model!G$4 -> 225204.72 | R27: =R19*Model!H$4 -> 222258.3 | S27: =S19*Model!I$4 -> 258295.28 | T27: =T19*Model!J$4 -> 303961.35 | U27: =U19*Model!K$4 -> 234991.12 | V27: =V19*Model!L$4 -> 252123.84 | W27: =W19*Model!M$4 -> 296975.4 | X27: =X19*Model!N$4 -> 334748.8 | Y27: =Y19*Model!O$4 -> 294866.78
N28: IoT | Q28: =Q20*Model!G$4 -> 35558.64 | R28: =R20*Model!H$4 -> 40410.6 | S28: =S20*Model!I$4 -> 53178.44 | T28: =T20*Model!J$4 -> 43423.05 | U28: =U20*Model!K$4 -> 41962.7 | V28: =V20*Model!L$4 -> 46689.6 | W28: =W20*Model!M$4 -> 49495.9 | X28: =X20*Model!N$4 -> 52304.5 | Y28: =Y20*Model!O$4 -> 68046.18
B29: Other Comprehesive Income (Losses) | C29: 41274 | D29: 13464 | E29: -21056 | F29: 37903 | G29: 31897 | H29: -254502 | I29: 95202 | J29: 71076 | K29: 53996 | N29: Automotive | Q29: =Q21*Model!G$4 -> 35558.64 | R29: =R21*Model!H$4 -> 33675.5 | S29: =S21*Model!I$4 -> 37984.6 | T29: =T21*Model!J$4 -> 34738.44 | U29: =U21*Model!K$4 -> 41962.7 | V29: =V21*Model!L$4 -> 46689.6 | W29: =W21*Model!M$4 -> 49495.9 | X29: =X21*Model!N$4 -> 52304.5 | Y29: =Y21*Model!O$4 -> 45364.12
B30: Comprehensive Income | C30: 266495 | D30: 261126 | E30: 304024 | F30: 412372 | G30: 392630 | H30: 142991 | I30: 546957 | J30: 576492 | K30: 626797 | N30: DCE | Q30: =Q22*Model!G$4 -> 11852.88 | R30: =R22*Model!H$4 -> 13470.2 | S30: =S22*Model!I$4 -> 7596.92 | T30: =T22*Model!J$4 -> 8684.61 | U30: =U22*Model!K$4 -> 8392.54 | V30: =V22*Model!L$4 -> 9337.92 | W30: =W22*Model!M$4 -> 9899.18 | X30: =X22*Model!N$4 -> 10460.9 | Y30: =Y22*Model!O$4 -> 11341.03
N31: others | Q31: =Q23*Model!G$4 -> 11852.88 | R31: =R23*Model!H$4 -> 13470.2 | S31: =S23*Model!I$4 -> 15193.84 | T31: =T23*Model!J$4 -> 17369.22 | U31: =U23*Model!K$4 -> 16785.08 | V31: =V23*Model!L$4 -> 18675.84 | W31: =W23*Model!M$4 -> 19798.36 | X31: =X23*Model!N$4 -> 20921.8 | Y31: =Y23*Model!O$4 -> 22682.06
B32: net income (losses) attributable to shareholder of the parent | C32: 225485 | D32: 247845 | E32: 325258 | F32: 374680 | G32: 361564 | H32: 398273 | I32: 452302 | J32: 505744 | K32: 572480 | N32: Total Rev | Q32: =SUM(Q26:Q31) -> 592644 | R32: =SUM(R26:R31) -> 673510 | S32: =SUM(S26:S31) -> 759692 | T32: =SUM(T26:T31) -> 868461 | U32: =SUM(U26:U31) -> 839254 | V32: =SUM(V26:V31) -> 933792 | W32: =SUM(W26:W31) -> 989918 | X32: =SUM(X26:X31) -> 1046090 | Y32: =SUM(Y26:Y31) -> 1134103
B33: NCI | C33: -264 | D33: -183 | E33: -178 | F33: -211 | G33: -831 | H33: -780 | I33: -547 | J33: -328 | K33: 321
C34: 225221 | D34: 247662 | E34: 325080 | F34: 374469 | G34: 360733 | H34: 397493 | I34: 451755 | J34: 505416 | K34: 572801 | N34: Revenue by Technology
N35: 3nm | Q35: =Q5*Model!G$4 -> 53337.96 | R35: =R5*Model!H$4 -> 101026.5 | S35: =S5*Model!I$4 -> 151938.4 | T35: =T5*Model!J$4 -> 225799.86 | U35: =U5*Model!K$4 -> 184635.88 | V35: =V5*Model!L$4 -> 224110.08 | W35: =W5*Model!M$4 -> 227681.14 | X35: =X5*Model!N$4 -> 292905.2 | Y35: =Y5*Model!O$4 -> 317548.84
B36: Cash flow Statement | N36: 5nm | Q36: =Q6*Model!G$4 -> 219278.28 | R36: =R6*Model!H$4 -> 235728.5 | S36: =S6*Model!I$4 -> 243101.44 | T36: =T6*Model!J$4 -> 295276.74 | U36: =U6*Model!K$4 -> 302131.44 | V36: =V6*Model!L$4 -> 336165.12 | W36: =W6*Model!M$4 -> 366269.66 | X36: =X6*Model!N$4 -> 366131.5 | Y36: =Y6*Model!O$4 -> 396936.05
B37: all figures in millions of New Taiwan Dollors NTD | C37: =C2 -> 45352 | D37: =D2 -> 45473 | E37: =E2 -> 45565 | F37: =F2 -> 45657 | G37: =G2 -> 45747 | H37: =H2 -> 45838 | I37: =I2 -> 45930 | J37: =J2 -> 46022 | K37: =K2 -> 46112 | N37: 7nm | Q37: =Q7*Model!G$4 -> 112602.36 | R37: =R7*Model!H$4 -> 114496.7 | S37: =S7*Model!I$4 -> 129147.64 | T37: =T7*Model!J$4 -> 121584.54 | U37: =U7*Model!K$4 -> 125888.1 | V37: =V7*Model!L$4 -> 130730.88 | W37: =W7*Model!M$4 -> 138588.52 | X37: =X7*Model!N$4 -> 146452.6 | Y37: =Y7*Model!O$4 -> 158774.42
N38: 16/17nm | Q38: =Q8*Model!G$4 -> 53337.96 | R38: =R8*Model!H$4 -> 60615.9 | S38: =S8*Model!I$4 -> 60775.36 | T38: =T8*Model!J$4 -> 60792.27 | U38: =U8*Model!K$4 -> 58747.78 | V38: =V8*Model!L$4 -> 65365.44 | W38: =W8*Model!M$4 -> 69294.26 | X38: =X8*Model!N$4 -> 62765.4 | Y38: =Y8*Model!O$4 -> 79387.21
B39: Cash from Operating Activities | N39: 28nm | Q39: =Q9*Model!G$4 -> 47411.52 | R39: =R9*Model!H$4 -> 53880.8 | S39: =S9*Model!I$4 -> 53178.44 | T39: =T9*Model!J$4 -> 52107.66 | U39: =U9*Model!K$4 -> 58747.78 | V39: =V9*Model!L$4 -> 65365.44 | W39: =W9*Model!M$4 -> 69294.26 | X39: =X9*Model!N$4 -> 62765.4 | Y39: =Y9*Model!O$4 -> 56705.15
B40: Income Before Income Tax | C40: 266543 | D40: 306311 | E40: 384187 | F40: 448798 | G40: 430895 | H40: 493036 | I40: 525369 | J40: 592363 | K40: 687800 | N40: 40/45nm | Q40: =Q10*Model!G$4 -> 29632.2 | R40: =R10*Model!H$4 -> 33675.5 | S40: =S10*Model!I$4 -> 30387.68 | T40: =T10*Model!J$4 -> 26053.83 | U40: =U10*Model!K$4 -> 25177.62 | V40: =V10*Model!L$4 -> 28013.76 | W40: =W10*Model!M$4 -> 29697.54 | X40: =X10*Model!N$4 -> 31382.7 | Y40: =Y10*Model!O$4 -> 34023.09
B41: D&A | C41: 159023 | D41: 165166 | E41: 168229 | F41: 170378 | G41: 175139 | H41: 188058 | I41: 162787 | J41: 162112 | K41: 165450 | N41: 65nm | Q41: =Q11*Model!G$4 -> 23705.76 | R41: =R11*Model!H$4 -> 20205.3 | S41: =S11*Model!I$4 -> 30387.68 | T41: =T11*Model!J$4 -> 34738.44 | U41: =U11*Model!K$4 -> 33570.16 | V41: =V11*Model!L$4 -> 28013.76 | W41: =W11*Model!M$4 -> 39596.72 | X41: =X11*Model!N$4 -> 41843.6 | Y41: =Y11*Model!O$4 -> 45364.12
B42: Share of Profits of Associates | C42: -878 | D42: -1152 | E42: -1561 | F42: -1289 | G42: -1368 | H42: -1222 | I42: -1424 | J42: -1483 | K42: -1685 | N42: 90nm | Q42: =Q12*Model!G$4 -> 5926.44 | R42: =R12*Model!H$4 -> 6735.1 | S42: =S12*Model!I$4 -> 7596.92 | T42: =T12*Model!J$4 -> 8684.61 | U42: =U12*Model!K$4 -> 8392.54 | V42: =V12*Model!L$4 -> 9337.92 | W42: =W12*Model!M$4 -> 9899.18 | X42: =X12*Model!N$4 -> 10460.9 | Y42: =Y12*Model!O$4 -> 11341.03
B43: Income Taxes Paid | C43: -1051 | D43: -88103 | E43: -93295 | F43: -1190 | G43: -1537 | H43: -127347 | I43: -137266 | J43: -1407 | K43: -1501 | N43: 0.11/0.13um | Q43: =Q13*Model!G$4 -> 17779.32 | R43: =R13*Model!H$4 -> 13470.2 | S43: =S13*Model!I$4 -> 15193.84 | T43: =T13*Model!J$4 -> 17369.22 | U43: =U13*Model!K$4 -> 16785.08 | V43: =V13*Model!L$4 -> 18675.84 | W43: =W13*Model!M$4 -> 9899.18 | X43: =X13*Model!N$4 -> 10460.9 | Y43: =Y13*Model!O$4 -> 11341.03
...
